# No Title

[Original Post](https://discourse.onlinedegree.iitm.ac.in/t/163247/87)

<p>For question 1 getting the below response … not sure what it means<br>
ythonError: Traceback (most recent call last): File “/lib/python312.zip/_pyodide/_base.py”, line 523, in eval_code .run(globals, locals) ^^^^^^^^^^^^^^^^^^^^ File “/lib/python312.zip/_pyodide/_base.py”, line 357, in run coroutine = eval(self.code, globals, locals) ^^^^^^^^^^^^^^^^^^^^^^^^^^^^^^^^ File “”, line 53, in  TypeError: unhashable type: ‘dict’</p>